Workbook

Sheet 13W Cash Forecast
A1: Alder Ridge Mechanical | 13-Week Cash Forecast
A2: Week ending 2026-06-26 | Version 09 | Preliminary treasury view
A4: Cash Flow Line | B4: 46206 | C4: 46213 | D4: 46220 | E4: 46227 | F4: 46234 | G4: 46241 | H4: 46248 | I4: 46255 | J4: 46262 | K4: 46269 | L4: 46276 | M4: 46283 | N4: 46290
A6: Beginning Cash | B6: =3233120 | C6: =B21 | D6: =C21 | E6: =D21 | F6: =E21 | G6: =F21 | H6: =G21 | I6: =H21 | J6: =I21 | ... N6: =M21
A8: Contract / Project Receipts | B8: 1936721 | C8: 1215973 | D8: 1142832 | E8: 1457411 | F8: 1114860 | G8: 1623668 | H8: 307043 | I8: 460038 | J8: 241150 | K8: 241150 | L8: 279370 | M8: 241150 | N8: 241150
A9: Service & Maintenance Receipts | B9: 195000 | C9: 195000 | D9: 220000 | E9: 195000 | F9: 195000 | G9: 195000 | H9: 220000 | I9: 195000 | J9: 195000 | K9: 195000 | L9: 220000 | M9: 195000 | N9: 195000
A10: Total Cash Inflows | B10: =SUM(B8:B9) | C10: =SUM(C8:C9) | D10: =SUM(D8:D9) | E10: =SUM(E8:E9) | F10: =SUM(F8:F9) | G10: =SUM(G8:G9) | H10: =SUM(H8:H9) | I10: =SUM(I8:I9) | ... N10: =SUM(N8:N9)
A12: Trade AP Disbursements | B12: 1306688 | C12: 913538 | D12: 552792 | E12: 380527 | F12: 288373 | G12: 230587 | H12: 113748 | I12: 0 | J12: 0 | K12: 0 | L12: 0 | M12: 0 | N12: 0
A13: Equipment / PO Commitments | B13: 0 | C13: 0 | D13: 0 | E13: 0 | F13: 532800 | G13: 387360 | H13: 135360 | I13: 237312 | J13: 204480 | K13: 0 | L13: 0 | M13: 0 | N13: 0
A14: Payroll | B14: 628000 | C14: 0 | D14: 628000 | E14: 0 | F14: 628000 | G14: 0 | H14: 628000 | I14: 0 | J14: 628000 | K14: 0 | L14: 628000 | M14: 0 | N14: 628000
A15: Payroll Taxes & Benefits | B15: 104000 | C15: 104000 | D15: 104000 | E15: 104000 | F15: 104000 | G15: 104000 | H15: 104000 | I15: 104000 | J15: 104000 | K15: 104000 | L15: 104000 | M15: 104000 | N15: 104000
A16: Occupancy | B16: 62000 | C16: 0 | D16: 0 | E16: 0 | F16: 0 | G16: 62000 | H16: 0 | I16: 0 | J16: 0 | K16: 62000 | L16: 0 | M16: 0 | N16: 0
A17: Debt Service | B17: 0 | C17: 0 | D17: 0 | E17: 0 | F17: 61000 | G17: 0 | H17: 0 | I17: 0 | J17: 61000 | K17: 0 | L17: 0 | M17: 0 | N17: 61000
A18: Capital Expenditures | B18: 0 | C18: 0 | D18: 0 | E18: 0 | F18: 0 | G18: 186000 | H18: 0 | I18: 0 | J18: 0 | K18: 0 | L18: 92000 | M18: 0 | N18: 0
A19: Total Cash Outflows | B19: =SUM(B12:B18) | C19: =SUM(C12:C18) | D19: =SUM(D12:D18) | E19: =SUM(E12:E18) | F19: =SUM(F12:F18) | G19: =SUM(G12:G18) | H19: =SUM(H12:H18) | I19: =SUM(I12:I18) | ... N19: =SUM(N12:N18)
A21: Ending Cash | B21: =B6+B10-B19+B24 | C21: =C6+C10-C19+C24 | D21: =D6+D10-D19+D24 | E21: =E6+E10-E19+E24 | F21: =F6+F10-F19+F24 | G21: =G6+G10-G19+G24 | H21: =H6+H10-H19+H24 | I21: =I6+I10-I19+I24 | ... N21: =N6+N10-N19+N24
A22: Minimum Operating Liquidity | B22: ='Assumptions'!$B$6 | C22: ='Assumptions'!$B$6 | D22: ='Assumptions'!$B$6 | E22: ='Assumptions'!$B$6 | F22: ='Assumptions'!$B$6 | G22: ='Assumptions'!$B$6 | H22: ='Assumptions'!$B$6 | I22: ='Assumptions'!$B$6 | ... N22: ='Assumptions'!$B$6
A23: Excess / (Shortfall) | B23: =B21-B22 | C23: =C21-C22 | D23: =D21-D22 | E23: =E21-E22 | F23: =F21-F22 | G23: =G21-G22 | H23: =H21-H22 | I23: =I21-I22 | ... N23: =N21-N22
A24: Revolver Draw / (Repayment) | B24: 0 | C24: 0 | D24: 0 | E24: 0 | F24: 0 | G24: 0 | H24: 0 | I24: 0 | J24: 0 | K24: 0 | L24: 0 | M24: 0 | N24: 0
A26: Liquidity Headroom After Financing | B26: =B21-B22 | C26: =C21-C22 | D26: =D21-D22 | E26: =E21-E22 | F26: =F21-F22 | G26: =G21-G22 | H26: =H21-H22 | I26: =I21-I22 | ... N26: =N21-N22

Sheet AR Timing
A1: AR Collection Timing
A2: As of 2026-06-26 | Contractual due dates may be overridden by documented controller collection notes
A5: Invoice | B5: Project | C5: Customer | D5: Invoice Date | E5: Due Date | F5: Open Amount | G5: Forecast Receipt Date | H5: Confidence | I5: Collection Note | J5: Included Week
A6: PAYAPP-ARM-2318-202308 | B6: ARM-2318 | C6: Columbia Biologics, Inc. | D6: 45169 | E6: 45199 | F6: 4815.52 | G6: 45199 | H6: Low | I6: Awaiting project-accountant follow-up | J6: =IFERROR(MATCH(G6,'13W Cash Forecast'!$B$4:$N$4,1),1)
A7: PAYAPP-ARM-2318-202309 | B7: ARM-2318 | C7: Columbia Biologics, Inc. | D7: 45199 | E7: 45229 | F7: 8317.97 | G7: 45229 | H7: Medium | I7: Contractual due date pending refreshed collection call | J7: =IFERROR(MATCH(G7,'13W Cash Forecast'!$B$4:$N$4,1),1)
A8: PAYAPP-ARM-2318-202310 | B8: ARM-2318 | C8: Columbia Biologics, Inc. | D8: 45230 | E8: 45260 | F8: 12978.68 | G8: 45260 | H8: Medium | I8: Contractual due date pending refreshed collection call | J8: =IFERROR(MATCH(G8,'13W Cash Forecast'!$B$4:$N$4,1),1)
A9: PAYAPP-ARM-2318-202311 | B9: ARM-2318 | C9: Columbia Biologics, Inc. | D9: 45260 | E9: 45290 | F9: 13114.51 | G9: 45290 | H9: Medium | I9: Contractual due date pending refreshed collection call | J9: =IFERROR(MATCH(G9,'13W Cash Forecast'!$B$4:$N$4,1),1)
A10: PAYAPP-ARM-2318-202312 | B10: ARM-2318 | C10: Columbia Biologics, Inc. | D10: 45291 | E10: 45321 | F10: 16454.51 | G10: 45321 | H10: Medium | I10: Contractual due date pending refreshed collection call | J10: =IFERROR(MATCH(G10,'13W Cash Forecast'!$B$4:$N$4,1),1)
A11: PAYAPP-ARM-2318-202401 | B11: ARM-2318 | C11: Columbia Biologics, Inc. | D11: 45322 | E11: 45352 | F11: 18898.65 | G11: 45352 | H11: Medium | I11: Contractual due date pending refreshed collection call | J11: =IFERROR(MATCH(G11,'13W Cash Forecast'!$B$4:$N$4,1),1)
A12: PAYAPP-ARM-2318-202402 | B12: ARM-2318 | C12: Columbia Biologics, Inc. | D12: 45351 | E12: 45381 | F12: 22631.12 | G12: 45381 | H12: Medium | I12: Contractual due date pending refreshed collection call | J12: =IFERROR(MATCH(G12,'13W Cash Forecast'!$B$4:$N$4,1),1)
A13: PAYAPP-ARM-2403-202402 | B13: ARM-2403 | C13: City of Riverton Facilities Bureau | D13: 45351 | E13: 45396 | F13: 2180.75 | G13: 45396 | H13: Low | I13: Awaiting project-accountant follow-up | J13: =IFERROR(MATCH(G13,'13W Cash Forecast'!$B$4:$N$4,1),1)
A14: PAYAPP-ARM-2318-202403 | B14: ARM-2318 | C14: Columbia Biologics, Inc. | D14: 45382 | E14: 45412 | F14: 29249.99 | G14: 45412 | H14: Medium | I14: Contractual due date pending refreshed collection call | J14: =IFERROR(MATCH(G14,'13W Cash Forecast'!$B$4:$N$4,1),1)
A15: PAYAPP-ARM-2403-202403 | B15: ARM-2403 | C15: City of Riverton Facilities Bureau | D15: 45382 | E15: 45427 | F15: 3905.99 | G15: 45427 | H15: Medium | I15: Contractual due date pending refreshed collection call | J15: =IFERROR(MATCH(G15,'13W Cash Forecast'!$B$4:$N$4,1),1)
A16: PAYAPP-ARM-2318-202404 | B16: ARM-2318 | C16: Columbia Biologics, Inc. | D16: 45412 | E16: 45442 | F16: 30938.48 | G16: 45442 | H16: Medium | I16: Contractual due date pending refreshed collection call | J16: =IFERROR(MATCH(G16,'13W Cash Forecast'!$B$4:$N$4,1),1)
A17: PAYAPP-ARM-2403-202404 | B17: ARM-2403 | C17: City of Riverton Facilities Bureau | D17: 45412 | E17: 45457 | F17: 6222.22 | G17: 45457 | H17: Medium | I17: Contractual due date pending refreshed collection call | J17: =IFERROR(MATCH(G17,'13W Cash Forecast'!$B$4:$N$4,1),1)
... A1041: AR-0031428 | B1041: Service | C1041: Portland Arts and Events - Central Campus Services | D1041: 46199 | E1041: 46244 | F1041: 1760.03 | G1041: 46244 | H1041: Medium | I1041: Contractual due date pending refreshed collection call | J1041: =IFERROR(MATCH(G1041,'13W Cash Forecast'!$B$4:$N$4,1),1)

Sheet AP & Commitments
A1: AP and Purchase Commitment Timing
A2: As of 2026-06-26 | Payment holds and equipment-release timing require explicit treasury treatment
A5: Source | B5: Document | C5: Project | D5: Vendor | E5: Due / Expected Date | F5: Open / Remaining Amount | G5: Payment Hold | H5: Forecast Payment Date | I5: Confidence | J5: Treasury Note | K5: Included Week
A6: AP | B6: AP-0004282 | C6: ARM-2409 | D6: Summit Electrical Contracting - Vancouver Group | E6: 46190 | F6: 31839.27 | G6: Yes | H6: 46190 | I6: Low | J6: Pending backcharge resolution and project-manager release | K6: =IFERROR(MATCH(H6,'13W Cash Forecast'!$B$4:$N$4,1),1)
A7: AP | B7: AP-0004290 | C7: ARM-2409 | D7: Cedar Mill Crane and Rigging - Gresham Services, LLC | E7: 46209 | F7: 35263.63 | G7: Yes | H7: 46209 | I7: Low | J7: Pending backcharge resolution and project-manager release | K7: =IFERROR(MATCH(H7,'13W Cash Forecast'!$B$4:$N$4,1),1)
A8: AP | B8: AP-0004887 | C8: ARM-2501 | D8: Pacific Crane and Rigging - Eugene LLC | E8: 46174 | F8: 5189.01 | G8: No | H8: 46174 | I8: Medium | J8: Pay to terms unless Controller releases otherwise | K8: =IFERROR(MATCH(H8,'13W Cash Forecast'!$B$4:$N$4,1),1)
A9: AP | B9: AP-0009838 | C9: G&A | D9: Northwest Fleet Service Center - Gresham Group | E9: 46174 | F9: 3519.1 | G9: No | H9: 46174 | I9: Medium | J9: Pay to terms unless Controller releases otherwise | K9: =IFERROR(MATCH(H9,'13W Cash Forecast'!$B$4:$N$4,1),1)
A10: AP | B10: AP-0009859 | C10: G&A | D10: Northwest Fleet Service Center - Gresham Group | E10: 46174 | F10: 1599.89 | G10: No | H10: 46174 | I10: Medium | J10: Pay to terms unless Controller releases otherwise | K10: =IFERROR(MATCH(H10,'13W Cash Forecast'!$B$4:$N$4,1),1)
A11: AP | B11: AP-0009861 | C11: G&A | D11: Cedar Mill Safety and Industrial Supply - Beaverton Services, LLC | E11: 46174 | F11: 1584.8 | G11: No | H11: 46174 | I11: Medium | J11: Pay to terms unless Controller releases otherwise | K11: =IFERROR(MATCH(H11,'13W Cash Forecast'!$B$4:$N$4,1),1)
A12: AP | B12: AP-0009882 | C12: G&A | D12: Cedar Mill Safety and Industrial Supply - Beaverton Services, LLC | E12: 46174 | F12: 1047.79 | G12: No | H12: 46174 | I12: Medium | J12: Pay to terms unless Controller releases otherwise | K12: =IFERROR(MATCH(H12,'13W Cash Forecast'!$B$4:$N$4,1),1)
A13: AP | B13: AP-0011875 | C13: G&A | D13: Tri-County Construction Advisory - Eugene LLC | E13: 46174 | F13: 3265.38 | G13: No | H13: 46174 | I13: Medium | J13: Pay to terms unless Controller releases otherwise | K13: =IFERROR(MATCH(H13,'13W Cash Forecast'!$B$4:$N$4,1),1)
A14: AP | B14: AP-0003875 | C14: ARM-2318 | D14: Pioneer Electrical Contracting - Salem Inc. | E14: 46175 | F14: 2734.19 | G14: No | H14: 46175 | I14: Medium | J14: Pay to terms unless Controller releases otherwise | K14: =IFERROR(MATCH(H14,'13W Cash Forecast'!$B$4:$N$4,1),1)
A15: AP | B15: AP-0004278 | C15: ARM-2409 | D15: Evergreen Crane and Rigging - Beaverton Company | E15: 46175 | F15: 7975.17 | G15: No | H15: 46175 | I15: Medium | J15: Pay to terms unless Controller releases otherwise | K15: =IFERROR(MATCH(H15,'13W Cash Forecast'!$B$4:$N$4,1),1)
A16: AP | B16: AP-0004283 | C16: ARM-2409 | D16: Columbia Mechanical Insulation - Bend Inc. | E16: 46175 | F16: 2583.28 | G16: No | H16: 46175 | I16: Medium | J16: Pay to terms unless Controller releases otherwise | K16: =IFERROR(MATCH(H16,'13W Cash Forecast'!$B$4:$N$4,1),1)
A17: AP | B17: AP-0004435 | C17: ARM-2412 | D17: Bridge City Testing and Balancing - Vancouver Group | E17: 46175 | F17: 4935.32 | G17: No | H17: 46175 | I17: Medium | J17: Pay to terms unless Controller releases otherwise | K17: =IFERROR(MATCH(H17,'13W Cash Forecast'!$B$4:$N$4,1),1)
... A441: PO | B441: PO-26-02027 | C441: ARM-2522 | D441: Consolidated Supply Co. - Portland | E441: 46255 | F441: 284000 | G441: No | H441: 46255 | I441: Low | J441: Release/payment timing to be confirmed with PM and vendor | K441: =IFERROR(MATCH(H441,'13W Cash Forecast'!$B$4:$N$4,1),1)

Sheet Assumptions
A1: Cash Forecast Assumptions
A2: Treasury policy, recurring cash flows and timing conventions
A5: Assumption | B5: Value | C5: Units | D5: Cadence / Date | E5: Owner | F5: Source / Rationale
A6: Minimum operating liquidity | B6: 1250000 | C6: USD | D6: Every week | E6: CFO | F6: Board-approved treasury policy
A7: Committed revolver capacity | B7: 4000000 | C7: USD | D7: Through 2027-09-30 | E7: CFO | F7: U.S. Bank facility amendment
A8: Service / maintenance weekly receipts | B8: 195000 | C8: USD | D8: Weekly | E8: Service Finance | F8: Trailing 8-week receipts excluding project work
A9: Biweekly gross payroll and field reimbursements | B9: 628000 | C9: USD | D9: Every other Friday | E9: Payroll Manager | F9: 6/26 payroll register, before July wage changes
A10: Weekly payroll tax and benefit remittance | B10: 104000 | C10: USD | D10: Weekly | E10: Controller | F10: Trailing 6-week average
A11: Monthly occupancy | B11: 58500 | C11: USD | D11: First Friday of month | E11: AP Manager | F11: Leases and CAM schedules
A12: Equipment debt service | B12: 57400 | C12: USD | D12: Month end | E12: Controller | F12: Debt amortization schedule
A13: Forecast convention | B13: Friday week ending | C13: Text | D13: 13 weeks | E13: Treasury | F13: Items on weekends roll to following week

Sheet Checks
A1: Cash Forecast Control Checks
A2: Version 09 preliminary controls
A5: Check | B5: Expected | C5: Actual / Delta | D5: Status | E5: Where to fix
A6: Opening cash agrees to accounting ledger | B6: Refresh required | C6: ='13W Cash Forecast'!B6-SUM('Assumptions'!B6*0) | D6: ="REFRESH" | E6: 13W Cash Forecast B6 / accounting cash balances
A7: All weeks roll beginning cash | B7: 0 | C7: =ABS('13W Cash Forecast'!C6-'13W Cash Forecast'!B21)+ABS('13W Cash Forecast'!D6-'13W Cash Forecast'!C21)+ABS('13W Cash Forecast'!E6-'13W Cash Forecast'!D21)+ABS('13W Cash Forecast'!F6-'13W Cash Forecast'!E21)+ABS('13W Cash Forecast'!G6-'13W Cash Forecast'!F21)+ABS('13W Cash Forecast'!H6-'13W Cash Forecast'!G21)+ABS('13W Cash Forecast'!I6-'13W Cash Forecast'!H21)+ABS('13W Cash Forecast'!J6-'13W Cash Forecast'!I21)+ABS('13W Cash Forecast'!K6-'13W Cash Forecast'!J21)+ABS('13W Cash Forecast'!L6-'13W Cash Forecast'!K21)+ABS('13W Cash Forecast'!M6-'13W Cash Forecast'!L21)+ABS('13W Cash Forecast'!N6-'13W Cash Forecast'!M21) | D7: =IF(ABS(C7)<0.01,"PASS","FAIL") | E7: 13W Cash Forecast row 6
A8: Ending cash arithmetic | B8: 0 | C8: =ABS('13W Cash Forecast'!B21-('13W Cash Forecast'!B6+'13W Cash Forecast'!B10-'13W Cash Forecast'!B19+'13W Cash Forecast'!B24))+ABS('13W Cash Forecast'!C21-('13W Cash Forecast'!C6+'13W Cash Forecast'!C10-'13W Cash Forecast'!C19+'13W Cash Forecast'!C24))+ABS('13W Cash Forecast'!D21-('13W Cash Forecast'!D6+'13W Cash Forecast'!D10-'13W Cash Forecast'!D19+'13W Cash Forecast'!D24))+ABS('13W Cash Forecast'!E21-('13W Cash Forecast'!E6+'13W Cash Forecast'!E10-'13W Cash Forecast'!E19+'13W Cash Forecast'!E24))+ABS('13W Cash Forecast'!F21-('13W Cash Forecast'!F6+'13W Cash Forecast'!F10-'13W Cash Forecast'!F19+'13W Cash Forecast'!F24))+ABS('13W Cash Forecast'!G21-('13W Cash Forecast'!G6+'13W Cash Forecast'!G10-'13W Cash Forecast'!G19+'13W Cash Forecast'!G24))+ABS('13W Cash Forecast'!H21-('13W Cash Forecast'!H6+'13W Cash Forecast'!H10-'13W Cash Forecast'!H19+'13W Cash Forecast'!H24))+ABS('13W Cash Forecast'!I21-('13W Cash Forecast'!I6+'13W Cash Forecast'!I10-'13W Cash Forecast'!I19+'13W Cash Forecast'!I24))+ABS('13W Cash Forecast'!J21-('13W Cash Forecast'!J6+'13W Cash Forecast'!J10-'13W Cash Forecast'!J19+'13W Cash Forecast'!J24))+ABS('13W Cash Forecast'!K21-('13W Cash Forecast'!K6+'13W Cash Forecast'!K10-'13W Cash Forecast'!K19+'13W Cash Forecast'!K24))+ABS('13W Cash Forecast'!L21-('13W Cash Forecast'!L6+'13W Cash Forecast'!L10-'13W Cash Forecast'!L19+'13W Cash Forecast'!L24))+ABS('13W Cash Forecast'!M21-('13W Cash Forecast'!M6+'13W Cash Forecast'!M10-'13W Cash Forecast'!M19+'13W Cash Forecast'!M24))+ABS('13W Cash Forecast'!N21-('13W Cash Forecast'!N6+'13W Cash Forecast'!N10-'13W Cash Forecast'!N19+'13W Cash Forecast'!N24)) | D8: =IF(ABS(C8)<0.01,"PASS","FAIL") | E8: 13W Cash Forecast row 21
A9: Held AP excluded until documented release | B9: 0 | C9: =COUNTIFS('AP & Commitments'!G6:G500,"Yes",'AP & Commitments'!H6:H500,"<2026-08-14") | D9: =IF(C9=0,"PASS","FAIL") | E9: AP & Commitments hold rows
A10: Forecast spans exactly 13 weeks | B10: 13 | C10: =COUNTA('13W Cash Forecast'!B4:N4) | D10: =IF(C10=B10,"PASS","FAIL") | E10: 13W Cash Forecast B4:N4

Sheet AP dump 6.26
A1: AP-310 export 6/26/26 18:07 - includes paid/closed items and predates the 6/30 cutoff. Filter was left on Vendor ID when saved.
A3: Bill | B3: Vendor ID | C3: Job | D3: Invoice date | E3: Due date | F3: Gross | G3: Paid | H3: Hold flag | I3: Hold reason | J3: Status
A4: AP-0005228 | B4: V-2440 | C4: ARM-2510 | D4: 2026-05-04 | E4: 2026-05-19 | F4: 16794.24 | G4: 16794.24 | J4: Paid
A5: AP-0005632 | B5: V-2265 | C5: ARM-2526 | D5: 2026-05-04 | E5: 2026-05-19 | F5: 11122.87 | G5: 11122.87 | J5: Paid
A6: AP-0005424 | B6: V-2450 | C6: ARM-2514 | D6: 2026-05-05 | E6: 2026-05-20 | F6: 4824.17 | G6: 4824.17 | J6: Paid
A7: AP-0009870 | B7: V-2235 | D7: 2026-05-05 | E7: 2026-05-20 | F7: 3700.48 | G7: 3700.48 | J7: Paid
A8: AP-0009891 | B8: V-2235 | D8: 2026-05-05 | E8: 2026-05-20 | F8: 3786.2 | G8: 3786.2 | J8: Paid
A9: AP-0003877 | B9: V-2305 | C9: ARM-2318 | D9: 2026-05-06 | E9: 2026-05-21 | F9: 34742.25 | G9: 34742.25 | J9: Paid
A10: AP-0005415 | B10: V-2355 | C10: ARM-2514 | D10: 2026-05-06 | E10: 2026-05-21 | F10: 13105.7 | G10: 13105.7 | J10: Paid
A11: AP-0009873 | B11: V-2265 | D11: 2026-05-06 | E11: 2026-05-21 | F11: 5436.5 | G11: 5436.5 | J11: Paid
A12: AP-0009894 | B12: V-2265 | D12: 2026-05-06 | E12: 2026-05-21 | F12: 3035.38 | G12: 3035.38 | J12: Paid
A13: AP-0005636 | B13: V-2310 | C13: ARM-2526 | D13: 2026-05-07 | E13: 2026-05-22 | F13: 5641.32 | G13: 5641.32 | J13: Paid
A14: AP-0009876 | B14: V-2290 | D14: 2026-05-07 | E14: 2026-05-22 | F14: 5131.28 | G14: 5131.28 | J14: Paid
A15: AP-0009897 | B15: V-2290 | D15: 2026-05-07 | E15: 2026-05-22 | F15: 4111.11 | G15: 4111.11 | J15: Paid
A16: AP-0012002 | B16: V-2480 | D16: 2026-05-07 | E16: 2026-05-22 | F16: 63000 | G16: 63000 | J16: Paid
A17: AP-0005232 | B17: V-2495 | C17: ARM-2510 | D17: 2026-05-08 | E17: 2026-05-23 | F17: 7790.26 | G17: 7790.26 | J17: Paid
A18: AP-0009879 | B18: V-2315 | D18: 2026-05-08 | E18: 2026-05-23 | F18: 4906.84 | G18: 4906.84 | J18: Paid
A19: AP-0009900 | B19: V-2315 | D19: 2026-05-08 | E19: 2026-05-23 | F19: 3748.14 | G19: 3748.14 | J19: Paid
A20: AP-0005713 | B20: V-2205 | C20: ARM-2605 | D20: 2026-05-09 | E20: 2026-05-24 | F20: 12185.03 | G20: 12185.03 | J20: Paid
A21: AP-0003876 | B21: V-2300 | C21: ARM-2318 | D21: 2026-05-10 | E21: 2026-05-25 | F21: 14123.79 | G21: 14123.79 | J21: Paid
A22: AP-0004284 | B22: V-2495 | C22: ARM-2409 | D22: 2026-05-10 | E22: 2026-05-25 | F22: 6632.28 | G22: 6632.28 | J22: Paid
A23: AP-0005078 | B23: V-2320 | C23: ARM-2506 | D23: 2026-05-11 | E23: 2026-05-26 | F23: 8009.35 | G23: 8009.35 | J23: Paid
A24: AP-0005238 | B24: V-2205 | C24: ARM-2510 | D24: 2026-05-11 | E24: 2026-05-26 | F24: 5610.98 | G24: 5610.98 | J24: Paid
A25: AP-0009862 | B25: V-2520 | D25: 2026-05-11 | E25: 2026-05-26 | F25: 6527.04 | G25: 6527.04 | J25: Paid
A26: AP-0009883 | B26: V-2520 | D26: 2026-05-11 | E26: 2026-05-26 | F26: 3252.76 | G26: 3252.76 | J26: Paid
A27: AP-0004097 | B27: V-2255 | C27: ARM-2403 | D27: 2026-05-12 | E27: 2026-05-27 | F27: 5503.38 | G27: 5503.38 | J27: Paid
A28: AP-0005580 | B28: V-2310 | C28: ARM-2522 | D28: 2026-05-13 | E28: 2026-05-28 | F28: 6167.58 | G28: 6167.58 | J28: Paid
A29: AP-0005085 | B29: V-2400 | C29: ARM-2506 | D29: 2026-05-14 | E29: 2026-05-29 | F29: 25914.51 | G29: 25914.51 | J29: Paid
A30: AP-0005630 | B30: V-2225 | C30: ARM-2526 | D30: 2026-05-14 | E30: 2026-05-29 | F30: 10196.1 | G30: 10196.1 | J30: Paid
A31: AP-0004681 | B31: V-2220 | C31: ARM-2417 | D31: 2026-05-15 | E31: 2026-05-30 | F31: 17991.76 | G31: 17991.76 | J31: Paid
A32: AP-0004688 | B32: V-2320 | C32: ARM-2417 | D32: 2026-05-15 | E32: 2026-05-30 | F32: 14722.51 | G32: 14722.51 | J32: Paid
A33: AP-0005406 | B33: V-2210 | C33: ARM-2514 | D33: 2026-05-15 | E33: 2026-05-30 | F33: 14440.19 | G33: 14440.19 | J33: Paid
A34: AP-0005677 | B34: V-2460 | C34: ARM-2602 | D34: 2026-05-15 | E34: 2026-05-30 | F34: 24874.1 | G34: 24874.1 | J34: Paid
A35: AP-0005500 | B35: V-2355 | C35: ARM-2518 | D35: 2026-05-16 | E35: 2026-05-31 | F35: 10885.74 | G35: 10885.74 | J35: Paid
A36: AP-0005505 | B36: V-2415 | C36: ARM-2518 | D36: 2026-05-16 | E36: 2026-05-31 | F36: 11892.37 | G36: 11892.37 | J36: Paid
A37: AP-0004887 | B37: V-2365 | C37: ARM-2501 | D37: 2026-05-17 | E37: 2026-06-01 | F37: 13775.23 | G37: 8586.22 | J37: Partially Paid
A38: AP-0009838 | B38: V-2304 | D38: 2026-04-17 | E38: 2026-06-01 | F38: 6224.59 | G38: 2705.49 | J38: Partially Paid
A39: AP-0009859 | B39: V-2304 | D39: 2026-04-17 | E39: 2026-06-01 | F39: 2976.65 | G39: 1376.76 | J39: Partially Paid
A40: AP-0009861 | B40: V-2513 | D40: 2026-05-02 | E40: 2026-06-01 | F40: 4978.39 | G40: 3393.59 | J40: Partially Paid
A41: AP-0009882 | B41: V-2513 | D41: 2026-05-02 | E41: 2026-06-01 | F41: 2932.76 | G41: 1884.97 | J41: Partially Paid
...

Sheet bank rec 6.26
A1: Pulled from Friday bank rec. Outstanding ACH list is incomplete after line 9; ledger cash must be refreshed at 6/30.
A3: Account | B3: Bank balance | C3: Outstanding checks | D3: ACH in transit | E3: Book balance | F3: Stmt date | G3: initials | H3: note
A4: Operating Cash - U.S. Bank 4431 | B4: 2615519.8 | C4: 95400 | D4: 33000 | E4: =B4-C4-D4 | F4: 2026-06-26 | G4: OL | H4: June 29-30 activity not included
A5: Payroll Cash - U.S. Bank 7718 | B5: 0 | C5: 0 | D5: 0 | E5: =B5-C5-D5 | F5: 2026-06-26 | G5: MP | H5: no reconciling items
A6: Money Market - Columbia State 1059 | B6: 1250000 | C6: 0 | D6: 0 | E6: =B6-C6-D6 | F6: 2026-06-26 | G6: NB | H6: no reconciling items
A7: Petty Cash and Field Advances | F7: 2026-06-26 | H7: no reconciling items

Sheet week map + overrides
A1: Helper tab built by MB. Date bands were copied from v8; several override reasons are blank even when a date was manually changed.
A3: week # | B3: week ending | C3: prior label | D3: payroll? | E3: occupancy? | F3: manual inflow adj | G3: manual outflow adj | H3: reason typed
A4: 1 | B4: 2026-07-03 | C4: wk 1 | D4: Y | E4: Y | F4: 0 | G4: 0
A5: 2 | B5: 2026-07-10 | C5: wk 2 | F5: 0 | G5: 0
A6: 3 | B6: 2026-07-17 | C6: wk 3 | D6: Y | F6: 0 | G6: 0
A7: 4 | B7: 2026-07-24 | C7: wk 4 | F7: 0 | G7: 0
A8: 5 | B8: 2026-07-31 | C8: wk 5 | D8: Y | E8: Y | F8: 125000 | G8: 0 | H8: possible timing shift--not approved
A9: 6 | B9: 2026-08-07 | C9: wk 6 | F9: 0 | G9: 0
A10: 7 | B10: 2026-08-14 | C10: wk 7 | D10: Y | F10: 0 | G10: 0
A11: 8 | B11: 2026-08-21 | C11: wk 8 | F11: 0 | G11: 85000
A12: 9 | B12: 2026-08-28 | C12: wk 9 | D12: Y | E12: Y | F12: 0 | G12: 0
A13: 10 | B13: 2026-09-04 | C13: wk 10 | F13: 0 | G13: 0
A14: 11 | B14: 2026-09-11 | C14: wk 11 | D14: Y | F14: 0 | G14: 0
A15: 12 | B15: 2026-09-18 | C15: wk 12 | F15: 0 | G15: 0
A16: 13 | B16: 2026-09-25 | C16: wk 13 | D16: Y | E16: Y | F16: 0 | G16: 0

Sheet old notes - keep
A1: Notes from v7/v8. Do not delete until the summer equipment releases are complete; some comments refer to superseded dates.
A3: typed | B3: by | C3: line/item | D3: note | E3: rolled?
A4: 6/12 | B4: DC | C4: Trane | D4: factory release moved once already; keep separate from normal AP | E4: yes
A5: 6/19 | B5: NB | C5: Columbia | D5: do not assume retainage in July | E5: yes
A6: 6/19 | B6: MB | C6: opening cash | D6: money market was missing from v7 | E6: fixed in v8
A7: 6/26 | B7: MB | C7: payroll | D7: still using pre-July run rate; update after 7/10 payroll | E7: NO
A8: 6/26 | B8: DC | C8: revolver | D8: show draw only when floor breached, not as a cushion | E8: yes
